Workbook

Sheet Start Here
C1: LRC Watchlist Builder — Swing & Investment
A2: Two tracks, one process: screen → shortlist → score → plan → review. US stocks via Finviz, JSE stocks via TradingView.
A4: The two tracks
A5: SWING (3–6 months) | B5: Weekly, every weekend. At least 5 new candidates — LONG (buy strong stocks in uptrends) or SHORT (sell weak stocks in downtrends). Set Direction on each row; the score, stop check, P/L and signals flip automatically. Lean long in RISK-ON markets, short in RISK-OFF. Tabs: How to Pick — Swing · Swing Watchlist · Weekly Review.
A6: INVESTMENT (5–10+ years) | B6: Monthly, first weekend. At least 5 new candidates. Excellent businesses at sensible prices, held while the thesis holds. Tabs: How to Pick — Investment · Investment Watchlist · Monthly Review.
A7: How the tabs fit
A8: Screener Settings | B8: The exact Finviz (US) and TradingView (JSE) filters: Swing Long, Swing Short and Investment. Save them as presets once.
A9: Watchlists | B9: Paste the screener numbers in the blue cells. Each stock gets a score, an A/B/C grade and a next step. Counters at the top check you hit the minimum of 5.
A10: Summary | B10: This week and this month at a glance, with the Top 5 by score.
A11: Reviews | B11: Tick-box checklists plus a log, so you follow the same process every time.
A12: Link to LRC process | B12: Swing A-grades → Technical Review in the LRC Stock Analysis Template for execution clearance. Investment A-grades → the full LRC Stock Analysis Template. Trades → LRC Portfolio Operations (Trade Log).
A13: Colour code
A14: Yellow cell, blue text | B14: You type here (percentages with the % sign, e.g. 12.5%)
A15: Grey cell | B15: Calculates — don't type over it
A16: Green / amber / red | B16: A / B / C grade, or a signal to act on
A17: First time setup | B17: This is a blank copy. Fill the yellow settings at the top of each watchlist first: review week (Saturday) and account size on the Swing Watchlist, review month on the Investment Watchlist. Update the S&P 500 and JSE 6-month performance every week.
A18: Important | B18: A screen is where research starts, not a buy signal. Scores rank candidates; your chart reading and judgement make the decision. Not financial advice.

Sheet Summary
C1: Watchlist Summary
A2: This week (swing) and this month (investment) at a glance: minimum-5 checks, grades, signals and the Top 5 by score.
A4: SWING — this week | H4: INVESTMENT — this month
A5: Week ending | D5: =IF('Swing Watchlist'!$C$4="","",'Swing Watchlist'!$C$4) -> 46316 | H5: Month | K5: =IF('Investment Watchlist'!$C$4="","",'Investment Watchlist'!$C$4) -> 46296
A6: New candidates | D6: ='Swing Watchlist'!U4 -> 13 | H6: New candidates | K6: ='Investment Watchlist'!L4 -> 10
A7: Minimum check | D7: ='Swing Watchlist'!V4 -> ✔ minimum met | H7: Minimum check | K7: ='Investment Watchlist'!M4 -> ✔ minimum met
A8: US / JSE · Long / Short | D8: ='Swing Watchlist'!U5&" · "&'Swing Watchlist'!U6 -> 13 / 0 · 3 / 10 | H8: US / JSE | K8: ='Investment Watchlist'!L5 -> 10 / 0
A9: Grade A / B / C | D9: =COUNTIFS('Swing Watchlist'!$A$11:$A$210,'Swing Watchlist'!$C$4,'Swing Watchlist'!$AK$11:$AK$210,"A")&" / "&COUNTIFS('Swing Watchlist'!$A$11:$A$210,'Swing Watchlist'!$C$4,'Swing Watchlist'!$AK$11:$AK$210,"B")&" / "&COUNTIFS('Swing Watchlist'!$A$11:$A$210,'Swing Watchlist'!$C$4,'Swing Watchlist'!$AK$11:$AK$210,"C") -> 0 / 9 / 4 | H9: Grade A / B / C | K9: =COUNTIFS('Investment Watchlist'!$A$9:$A$158,'Investment Watchlist'!$C$4,'Investment Watchlist'!$AG$9:$AG$158,"A")&" / "&COUNTIFS('Investment Watchlist'!$A$9:$A$158,'Investment Watchlist'!$C$4,'Investment Watchlist'!$AG$9:$AG$158,"B")&" / "&COUNTIFS('Investment Watchlist'!$A$9:$A$158,'Investment Watchlist'!$C$4,'Investment Watchlist'!$AG$9:$AG$158,"C") -> 5 / 4 / 1
A10: Open positions | D10: =COUNTIF('Swing Watchlist'!$AP$11:$AP$210,"Open position") -> 0 | H10: Owned | K10: =COUNTIF('Investment Watchlist'!$AI$9:$AI$158,"Owned") -> 0
A11: Sell / cover / take-profit signals | D11: =COUNTIF('Swing Watchlist'!$AU$11:$AU$210,"SELL*")+COUNTIF('Swing Watchlist'!$AU$11:$AU$210,"COVER*")+COUNTIF('Swing Watchlist'!$AU$11:$AU$210,"TAKE*") -> 0 | H11: Sent to full analysis | K11: =COUNTIF('Investment Watchlist'!$AH$9:$AH$158,"Full*") -> 5
A12: Review signals | D12: =COUNTIF('Swing Watchlist'!$AU$11:$AU$210,"REVIEW*") -> 0 | H12: Review signals | K12: =COUNTIF('Investment Watchlist'!$AH$9:$AH$158,"REVIEW*") -> 0
A14: Top 5 swing candidates this week | H14: Top 5 investment candidates this month
A15: # | B15: Ticker | C15: L/S | D15: Score | E15: Grade | F15: Next step | H15: # | I15: Ticker | J15: Mkt | K15: Score | L15: Grade | M15: Next step
A16: 1 | B16: =IFERROR(INDEX('Swing Watchlist'!$C$11:$C$210,MATCH(LARGE('Swing Watchlist'!$AX$11:$AX$210,1),'Swing Watchlist'!$AX$11:$AX$210,0)),"") -> NKE | C16: =IFERROR(IF(INDEX('Swing Watchlist'!$F$11:$F$210,MATCH(LARGE('Swing Watchlist'!$AX$11:$AX$210,1),'Swing Watchlist'!$AX$11:$AX$210,0))="Short","Short","Long"),"") -> Short | D16: =IFERROR(INDEX('Swing Watchlist'!$AJ$11:$AJ$210,MATCH(LARGE('Swing Watchlist'!$AX$11:$AX$210,1),'Swing Watchlist'!$AX$11:$AX$210,0)),"") -> 13 | E16: =IFERROR(INDEX('Swing Watchlist'!$AK$11:$AK$210,MATCH(LARGE('Swing Watchlist'!$AX$11:$AX$210,1),'Swing Watchlist'!$AX$11:$AX$210,0)),"") -> B | F16: =IFERROR(INDEX('Swing Watchlist'!$AU$11:$AU$210,MATCH(LARGE('Swing Watchlist'!$AX$11:$AX$210,1),'Swing Watchlist'!$AX$11:$AX$210,0)),"") -> Watch — wait for setup | H16: 1 | I16: =IFERROR(INDEX('Investment Watchlist'!$C$9:$C$158,MATCH(LARGE('Investment Watchlist'!$AP$9:$AP$158,1),'Investment Watchlist'!$AP$9:$AP$158,0)),"") -> INTU | J16: =IFERROR(INDEX('Investment Watchlist'!$B$9:$B$158,MATCH(LARGE('Investment Watchlist'!$AP$9:$AP$158,1),'Investment Watchlist'!$AP$9:$AP$158,0)),"") -> US | K16: =IFERROR(INDEX('Investment Watchlist'!$AF$9:$AF$158,MATCH(LARGE('Investment Watchlist'!$AP$9:$AP$158,1),'Investment Watchlist'!$AP$9:$AP$158,0)),"") -> 24 | L16: =IFERROR(INDEX('Investment Watchlist'!$AG$9:$AG$158,MATCH(LARGE('Investment Watchlist'!$AP$9:$AP$158,1),'Investment Watchlist'!$AP$9:$AP$158,0)),"") -> A | M16: =IFERROR(INDEX('Investment Watchlist'!$AH$9:$AH$158,MATCH(LARGE('Investment Watchlist'!$AP$9:$AP$158,1),'Investment Watchlist'!$AP$9:$AP$158,0)),"") -> Full LRC Stock Analysis
A17: 2 | B17: =IFERROR(INDEX('Swing Watchlist'!$C$11:$C$210,MATCH(LARGE('Swing Watchlist'!$AX$11:$AX$210,2),'Swing Watchlist'!$AX$11:$AX$210,0)),"") -> KEYS | C17: =IFERROR(IF(INDEX('Swing Watchlist'!$F$11:$F$210,MATCH(LARGE('Swing Watchlist'!$AX$11:$AX$210,2),'Swing Watchlist'!$AX$11:$AX$210,0))="Short","Short","Long"),"") -> Short | D17: =IFERROR(INDEX('Swing Watchlist'!$AJ$11:$AJ$210,MATCH(LARGE('Swing Watchlist'!$AX$11:$AX$210,2),'Swing Watchlist'!$AX$11:$AX$210,0)),"") -> 12 | E17: =IFERROR(INDEX('Swing Watchlist'!$AK$11:$AK$210,MATCH(LARGE('Swing Watchlist'!$AX$11:$AX$210,2),'Swing Watchlist'!$AX$11:$AX$210,0)),"") -> B | F17: =IFERROR(INDEX('Swing Watchlist'!$AU$11:$AU$210,MATCH(LARGE('Swing Watchlist'!$AX$11:$AX$210,2),'Swing Watchlist'!$AX$11:$AX$210,0)),"") -> Watch — wait for setup | H17: 2 | I17: =IFERROR(INDEX('Investment Watchlist'!$C$9:$C$158,MATCH(LARGE('Investment Watchlist'!$AP$9:$AP$158,2),'Investment Watchlist'!$AP$9:$AP$158,0)),"") -> DECK | J17: =IFERROR(INDEX('Investment Watchlist'!$B$9:$B$158,MATCH(LARGE('Investment Watchlist'!$AP$9:$AP$158,2),'Investment Watchlist'!$AP$9:$AP$158,0)),"") -> US | K17: =IFERROR(INDEX('Investment Watchlist'!$AF$9:$AF$158,MATCH(LARGE('Investment Watchlist'!$AP$9:$AP$158,2),'Investment Watchlist'!$AP$9:$AP$158,0)),"") -> 21 | L17: =IFERROR(INDEX('Investment Watchlist'!$AG$9:$AG$158,MATCH(LARGE('Investment Watchlist'!$AP$9:$AP$158,2),'Investment Watchlist'!$AP$9:$AP$158,0)),"") -> A | M17: =IFERROR(INDEX('Investment Watchlist'!$AH$9:$AH$158,MATCH(LARGE('Investment Watchlist'!$AP$9:$AP$158,2),'Investment Watchlist'!$AP$9:$AP$158,0)),"") -> Full LRC Stock Analysis
A18: 3 | B18: =IFERROR(INDEX('Swing Watchlist'!$C$11:$C$210,MATCH(LARGE('Swing Watchlist'!$AX$11:$AX$210,3),'Swing Watchlist'!$AX$11:$AX$210,0)),"") -> NVDA | C18: =IFERROR(IF(INDEX('Swing Watchlist'!$F$11:$F$210,MATCH(LARGE('Swing Watchlist'!$AX$11:$AX$210,3),'Swing Watchlist'!$AX$11:$AX$210,0))="Short","Short","Long"),"") -> Long | D18: =IFERROR(INDEX('Swing Watchlist'!$AJ$11:$AJ$210,MATCH(LARGE('Swing Watchlist'!$AX$11:$AX$210,3),'Swing Watchlist'!$AX$11:$AX$210,0)),"") -> 12 | E18: =IFERROR(INDEX('Swing Watchlist'!$AK$11:$AK$210,MATCH(LARGE('Swing Watchlist'!$AX$11:$AX$210,3),'Swing Watchlist'!$AX$11:$AX$210,0)),"") -> B | F18: =IFERROR(INDEX('Swing Watchlist'!$AU$11:$AU$210,MATCH(LARGE('Swing Watchlist'!$AX$11:$AX$210,3),'Swing Watchlist'!$AX$11:$AX$210,0)),"") -> Watch — wait for setup | H18: 3 | I18: =IFERROR(INDEX('Investment Watchlist'!$C$9:$C$158,MATCH(LARGE('Investment Watchlist'!$AP$9:$AP$158,3),'Investment Watchlist'!$AP$9:$AP$158,0)),"") -> NVDA | J18: =IFERROR(INDEX('Investment Watchlist'!$B$9:$B$158,MATCH(LARGE('Investment Watchlist'!$AP$9:$AP$158,3),'Investment Watchlist'!$AP$9:$AP$158,0)),"") -> US | K18: =IFERROR(INDEX('Investment Watchlist'!$AF$9:$AF$158,MATCH(LARGE('Investment Watchlist'!$AP$9:$AP$158,3),'Investment Watchlist'!$AP$9:$AP$158,0)),"") -> 21 | L18: =IFERROR(INDEX('Investment Watchlist'!$AG$9:$AG$158,MATCH(LARGE('Investment Watchlist'!$AP$9:$AP$158,3),'Investment Watchlist'!$AP$9:$AP$158,0)),"") -> A | M18: =IFERROR(INDEX('Investment Watchlist'!$AH$9:$AH$158,MATCH(LARGE('Investment Watchlist'!$AP$9:$AP$158,3),'Investment Watchlist'!$AP$9:$AP$158,0)),"") -> Full LRC Stock Analysis
A19: 4 | B19: =IFERROR(INDEX('Swing Watchlist'!$C$11:$C$210,MATCH(LARGE('Swing Watchlist'!$AX$11:$AX$210,4),'Swing Watchlist'!$AX$11:$AX$210,0)),"") -> GOOGL | C19: =IFERROR(IF(INDEX('Swing Watchlist'!$F$11:$F$210,MATCH(LARGE('Swing Watchlist'!$AX$11:$AX$210,4),'Swing Watchlist'!$AX$11:$AX$210,0))="Short","Short","Long"),"") -> Short | D19: =IFERROR(INDEX('Swing Watchlist'!$AJ$11:$AJ$210,MATCH(LARGE('Swing Watchlist'!$AX$11:$AX$210,4),'Swing Watchlist'!$AX$11:$AX$210,0)),"") -> 11 | E19: =IFERROR(INDEX('Swing Watchlist'!$AK$11:$AK$210,MATCH(LARGE('Swing Watchlist'!$AX$11:$AX$210,4),'Swing Watchlist'!$AX$11:$AX$210,0)),"") -> B | F19: =IFERROR(INDEX('Swing Watchlist'!$AU$11:$AU$210,MATCH(LARGE('Swing Watchlist'!$AX$11:$AX$210,4),'Swing Watchlist'!$AX$11:$AX$210,0)),"") -> Watch — wait for setup | H19: 4 | I19: =IFERROR(INDEX('Investment Watchlist'!$C$9:$C$158,MATCH(LARGE('Investment Watchlist'!$AP$9:$AP$158,4),'Investment Watchlist'!$AP$9:$AP$158,0)),"") -> PCTY | J19: =IFERROR(INDEX('Investment Watchlist'!$B$9:$B$158,MATCH(LARGE('Investment Watchlist'!$AP$9:$AP$158,4),'Investment Watchlist'!$AP$9:$AP$158,0)),"") -> US | K19: =IFERROR(INDEX('Investment Watchlist'!$AF$9:$AF$158,MATCH(LARGE('Investment Watchlist'!$AP$9:$AP$158,4),'Investment Watchlist'!$AP$9:$AP$158,0)),"") -> 20 | L19: =IFERROR(INDEX('Investment Watchlist'!$AG$9:$AG$158,MATCH(LARGE('Investment Watchlist'!$AP$9:$AP$158,4),'Investment Watchlist'!$AP$9:$AP$158,0)),"") -> A | M19: =IFERROR(INDEX('Investment Watchlist'!$AH$9:$AH$158,MATCH(LARGE('Investment Watchlist'!$AP$9:$AP$158,4),'Investment Watchlist'!$AP$9:$AP$158,0)),"") -> Full LRC Stock Analysis
A20: 5 | B20: =IFERROR(INDEX('Swing Watchlist'!$C$11:$C$210,MATCH(LARGE('Swing Watchlist'!$AX$11:$AX$210,5),'Swing Watchlist'!$AX$11:$AX$210,0)),"") -> ANET | C20: =IFERROR(IF(INDEX('Swing Watchlist'!$F$11:$F$210,MATCH(LARGE('Swing Watchlist'!$AX$11:$AX$210,5),'Swing Watchlist'!$AX$11:$AX$210,0))="Short","Short","Long"),"") -> Short | D20: =IFERROR(INDEX('Swing Watchlist'!$AJ$11:$AJ$210,MATCH(LARGE('Swing Watchlist'!$AX$11:$AX$210,5),'Swing Watchlist'!$AX$11:$AX$210,0)),"") -> 10 | E20: =IFERROR(INDEX('Swing Watchlist'!$AK$11:$AK$210,MATCH(LARGE('Swing Watchlist'!$AX$11:$AX$210,5),'Swing Watchlist'!$AX$11:$AX$210,0)),"") -> B | F20: =IFERROR(INDEX('Swing Watchlist'!$AU$11:$AU$210,MATCH(LARGE('Swing Watchlist'!$AX$11:$AX$210,5),'Swing Watchlist'!$AX$11:$AX$210,0)),"") -> Watch — wait for setup | H20: 5 | I20: =IFERROR(INDEX('Investment Watchlist'!$C$9:$C$158,MATCH(LARGE('Investment Watchlist'!$AP$9:$AP$158,5),'Investment Watchlist'!$AP$9:$AP$158,0)),"") -> META | J20: =IFERROR(INDEX('Investment Watchlist'!$B$9:$B$158,MATCH(LARGE('Investment Watchlist'!$AP$9:$AP$158,5),'Investment Watchlist'!$AP$9:$AP$158,0)),"") -> US | K20: =IFERROR(INDEX('Investment Watchlist'!$AF$9:$AF$158,MATCH(LARGE('Investment Watchlist'!$AP$9:$AP$158,5),'Investment Watchlist'!$AP$9:$AP$158,0)),"") -> 18 | L20: =IFERROR(INDEX('Investment Watchlist'!$AG$9:$AG$158,MATCH(LARGE('Investment Watchlist'!$AP$9:$AP$158,5),'Investment Watchlist'!$AP$9:$AP$158,0)),"") -> A | M20: =IFERROR(INDEX('Investment Watchlist'!$AH$9:$AH$158,MATCH(LARGE('Investment Watchlist'!$AP$9:$AP$158,5),'Investment Watchlist'!$AP$9:$AP$158,0)),"") -> Full LRC Stock Analysis

Sheet How to Pick — Swing
C1: Swing trades — LONG and SHORT (hold 3–6 months)
A2: Goal: buy strong stocks in uptrends (Long) and sell weak stocks in downtrends (Short), each at a low-risk point with a stop and a target. Target: at least 5 new candidates a week, any mix of long/short, US and JSE.
A4: Step-by-step (about 60–90 minutes)
A5: 1. Check the market (5 min) | B5: Is the S&P 500 above its 200-day average? Is the JSE All Share above its 200-day average? Both above = RISK-ON: mostly longs. Both below = RISK-OFF: mostly shorts. One of each = MIXED: both, smaller sizes. Record it on the Weekly Review tab — it tells you which way to lean.
A6: 2. Run BOTH screens (15 min) | B6: Run the LONG preset and the SHORT preset on the 'Screener Settings' tab — Finviz for US, TradingView for JSE. Save all four as presets so it's one click next week.
A7: 3. Sort and shortlist (15 min) | B7: LONGS: sort by 'Perf Half' highest first; keep clean uptrends (higher highs, higher lows, price above a rising 50-day). SHORTS: sort by 'Perf Half' lowest first; keep clean downtrends (lower highs, lower lows, price below a falling 50-day).
A8: 4. Find the setup (20 min) | B8: LONG setups: breakout from a base · pullback to the 20/50-day in an uptrend · trend continuation · earnings gap up that holds. SHORT setups: breakdown below support · rally into a falling 50-day that fails · downtrend continuation · earnings gap down that holds. No clear setup = Watch.
A9: 5. Plan the trade (10 min) | B9: LONG: entry above the trigger, stop BELOW (last swing low or ~2×ATR), target ABOVE. SHORT: entry below the trigger, stop ABOVE (last swing high or ~2×ATR), target BELOW (next support). Reward:risk under 2x = skip. The sheet flags a stop on the wrong side.
A10: 6. Enter in the sheet (10 min) | B10: Add at least 5 candidates on 'Swing Watchlist' with this week's date and set Direction = Long or Short. Paste the screener numbers — the score flips automatically for shorts. A = run the Technical Review (reversed for shorts) and get clearance; B = watch; C = drop.
A11: 7. Review what you hold (10 min) | B11: Update 'Price now' on every 'Open position' and read the Review signal. Long: SELL if stop hit. Short: COVER (buy back) if stop hit. Both: TAKE PROFIT at target; REVIEW if the trend breaks (long below / short above the 50-day) or no progress after 6 weeks; exit at 6 months.
A12: What the scores mean (Long ↔ Short)
A13: Trend /4 | B13: LONG: +1 each for price above the 20-, 50- and 200-day averages, and 50-day above 200-day. SHORT: +1 each for price BELOW them, and 50-day BELOW 200-day.
A14: Momentum /4 | B14: LONG: RSI 50–70 = 2 (40–50 or 70–75 = 1); 6-month performance beats the index = 2 (positive = 1). SHORT: RSI 30–50 = 2 (25–30 or 50–60 = 1); 6-month performance lags the index = 2 (negative = 1).
A15: Range position /2 | B15: LONG: within 10% of the 52-week HIGH = 2 (25% = 1) — leaders trade near highs. SHORT: within 10% of the 52-week LOW = 2 (25% = 1) — laggards trade near lows.
A16: Liquidity /2 | B16: Average daily value above the minimum in settings = 2; above a quarter of it = 1. Applies to both — shorts especially need liquidity.
A17: Fuel /2 | B17: LONG: earnings growing this year = 1. SHORT: earnings shrinking = 1. Both: relative volume 1.5x+ = 1.
A18: Reward:risk /4 | B18: 3x or better = 4; 2x–3x = 2; below 2x = 0. Fill entry, stop and target first (works both ways).
A19: Event risk | B19: −2 if results are due within 14 days of the review date — gap risk either way.
A20: Squeeze risk (shorts) | B20: −1 if short float is 20%+. Heavily shorted stocks can jump violently when shorts rush to buy back.
A21: Grades | B21: A = 14+ out of 18 · B = 10–13 · C = under 10. Same scale for longs and shorts.
A22: Why fundamentals matter in swing trading
A23: The short answer | B23: Price and trend tell you WHEN; fundamentals tell you WHY. Over 3–12 months a stock usually follows its earnings: big funds buy companies whose profits and sales are accelerating and sell the ones that are slowing. The longer you hold, the more fundamentals matter.
A24: What to look at (long) | B24: Latest quarter EPS growth 15%+ and sales growth 10%+ (versus a year ago), earnings beating forecasts, profit margins steady or rising. Avoid longs with falling sales even if the chart looks good.
A25: What to look at (short) | B25: Falling EPS and sales, earnings misses, margins shrinking, high debt. The best shorts are weak businesses in downtrends — not good businesses that dipped.
A26: What NOT to do | B26: Don't use deep valuation (P/E, DCF) to time swing trades — expensive stocks can keep rising and cheap ones keep falling for months. Valuation belongs to the investment track and the LRC Stock Analysis Template.
A27: Short-selling basics
A28: How a short works | B28: You sell first and buy back later. You profit if the price FALLS. P/L in the sheet = 1 − price now ÷ entry. Losses grow if the price RISES, and in theory have no ceiling — so the stop is not optional.
A29: How to short | B29: US: shares marked 'Shortable' at your broker, or CFDs. JSE: CFDs (or single-stock futures) — normal JSE share accounts can't short. Check borrow fees and dividends: a short pays the dividend.
A30: When to avoid shorts | B30: Short float above 20%, a takeover rumour, results within 2 weeks, or a strong RISK-ON market. Never short just because a stock 'looks expensive'.
A31: Rules that keep you safe
A32: Risk | B32: Never risk more than 1% of the account on one trade (the sheet sizes it). Never move a stop AGAINST you: not down on a long, not up on a short.
A33: Concentration | B33: No more than 2 open trades in the same sector, no more than 8 open swing trades, and no more than 4 shorts at once.
A34: Leverage | B34: On a margin account or CFD, size by the risk amount, not by the margin available.
A35: Discipline | B35: Write the plan before you trade. If the price never reaches the entry, there is no trade.

Sheet Swing Watchlist
C1: Swing Watchlist — weekly, LONG and SHORT (hold 3 to 6 months)
A2: Every week add at least 5 candidates — buys (Long) or sells/shorts (Short), US and JSE. Choose the Direction first: scores, reward:risk, position size, P/L and the review signal all follow it. Type percentages with the % sign.
A4: Current review week ending | C4: 46316 | D4: Saturday of the review week. Counts and the Top 5 use this date. | J4: S&P 500 6-month performance | L4: 0.1437 | M4: Benchmark for relative strength (Finviz: SPY 'Perf Half'). | S4: This week's candidates | U4: =COUNTIFS($A$11:$A$210,$C$4,$C$11:$C$210,"?*") -> 13 | V4: =IF(U4>=$C$5,"✔ minimum met","⚠ need "&($C$5-U4)&" more") -> ✔ minimum met
A5: Minimum new candidates per week | C5: 5 | D5: House rule (longs + shorts together). | J5: JSE All Share 6-month performance | L5: -0.0744 | M5: JSE All Share 6-month: 13 Oct 2026 vs 9 Apr 2026 (−7.4%). No JSE names this week. | S5: US / JSE this week | U5: =COUNTIFS($A$11:$A$210,$C$4,$B$11:$B$210,"US")&" / "&COUNTIFS($A$11:$A$210,$C$4,$B$11:$B$210,"JSE") -> 13 / 0
A6: Trading account size (base currency) | C6: 45.78 | D6: Est. broker equity 14 Oct ($45.78 = 48.66 + ΔUPNL − Δswap vs 3 Oct export) — replace with the broker figure. For position sizing. | J6: Liquidity: min avg daily value — US (millions $) | L6: 20 | M6: $20m+ a day trades easily. | S6: Long / Short this week | U6: =COUNTIFS($A$11:$A$210,$C$4,$C$11:$C$210,"?*",$F$11:$F$210,"<>Short")&" / "&COUNTIFS($A$11:$A$210,$C$4,$F$11:$F$210,"Short") -> 3 / 10
A7: Risk per trade (% of account) | C7: 0.01 | D7: 1% means a stop-out loses 1% of the account. | J7: Liquidity: min avg daily value — JSE (millions R) | L7: 20 | M7: R20m+ a day; smaller JSE shares are hard to exit. | S7: A-grades / open positions | U7: =COUNTIFS($A$11:$A$210,$C$4,$AK$11:$AK$210,"A")&" / "&COUNTIF($AP$11:$AP$210,"Open position") -> 0 / 0
A9: INPUTS FROM FINVIZ / TRADINGVIEW + YOUR TRADE PLAN | AB9: SCORE (automatic — follows Direction) | AL9: PLAN & POSITION SIZE | AP9: STATUS & MONITORING
A10: Week ending | B10: Market | C10: Ticker | D10: Company | E10: Sector | F10: Direction | G10: Price | H10: Mkt cap (bn) | I10: Avg volume (shares) | J10: Avg daily value (m) | K10: vs SMA20 | L10: vs SMA50 | M10: vs SMA200 | N10: RSI (14) | O10: Perf Quarter | P10: Perf Half | Q10: From 52W High | R10: From 52W Low | S10: Rel Volume | T10: EPS growth this yr | U10: Short float | V10: Next earnings | W10: ATR (14) | X10: Setup | Y10: Entry | Z10: Stop | AA10: Target | AB10: Trend /4 | AC10: Momentum /4 | AD10: Range position /2 | AE10: Liquidity /2 | AF10: Fuel /2 | AG10: Reward:risk /4 | AH10: Event risk | AI10: Squeeze risk | AJ10: SCORE /18 | AK10: Grade | AL10: Reward : risk | AM10: Risk / share | AN10: Position size (shares) | AO10: Position value | AP10: Status | AQ10: Entry date | AR10: Price now | AS10: P/L % | AT10: Days held | AU10: Review signal | AV10: Notes / chart
A11: 46298 | B11: US | C11: PCTY | D11: Paylocity Holding Corporation | E11: Technology | F11: Long | G11: 144.47 | H11: 7.67 | I11: 681700 | J11: =IF(OR(G11="",I11=""),"",G11*I11/1000000) -> 98.485199 | K11: -0.0016 | L11: -0.0137 | M11: 0.1551 | N11: 48.5 | O11: 0.2552 | P11: 0.3611 | Q11: -0.1078 | R11: 0.5536 | S11: 0.79 | T11: 0.0511 | U11: 0.0651 | V11: 46329 | W11: 4.15 | X11: LONG: Pullback to 20/50-day avg | Y11: 149 | Z11: 140.7 | AA11: 173.95 | AB11: =IF(C11="","",IF(F11="Short",(AND(M11<>"",N(M11)<0))+(AND(L11<>"",N(L11)<0))+(AND(K11<>"",N(K11)<0))+AND(L11<>"",M11<>"",N(M11)<N(L11)),(N(M11)>0)+(N(L11)>0)+(N(K11)>0)+AND(L11<>"",M11<>"",N(M11)>N(L11)))) -> 2 | AC11: =IF(C11="","",IF(F11="Short",IF(N11="",0,IF(AND(N11>=30,N11<=50),2,IF(OR(AND(N11>=25,N11<30),AND(N11>50,N11<=60)),1,0)))+IF(P11="",0,IF(AND(IF(B11="JSE",$L$5,$L$4)<>"",P11<IF(B11="JSE",$L$5,$L$4)),2,IF(P11<0,1,0))),IF(N11="",0,IF(AND(N11>=50,N11<=70),2,IF(OR(AND(N11>=40,N11<50),AND(N11>70,N11<=75)),1,0)))+IF(P11="",0,IF(AND(IF(B11="JSE",$L$5,$L$4)<>"",P11>IF(B11="JSE",$L$5,$L$4)),2,IF(P11>0,1,0))))) -> 3 | AD11: =IF(C11="","",IF(F11="Short",IF(R11="",0,IF(R11<=0.1,2,IF(R11<=0.25,1,0))),IF(Q11="",0,IF(Q11>=-0.1,2,IF(Q11>=-0.25,1,0))))) -> 1 | AE11: =IF(C11="","",IF(J11="",0,IF(J11>=IF(B11="JSE",$L$7,$L$6),2,IF(J11>=IF(B11="JSE",$L$7,$L$6)/4,1,0)))) -> 2 | AF11: =IF(C11="","",IF(F11="Short",AND(T11<>"",N(T11)<0),N(T11)>0)+(N(S11)>=1.5)) -> 1 | AG11: =IF(C11="","",IF(AL11="",0,IF(AL11>=3,4,IF(AL11>=2,2,0)))) -> 4 | AH11: =IF(C11="","",IF(AND(ISNUMBER(V11),ISNUMBER(A11),V11>=A11,V11-A11<=14),-2,0)) -> 0 | AI11: =IF(C11="","",IF(AND(F11="Short",N(U11)>=0.2),-1,0)) -> 0 | AJ11: =IF(C11="","",SUM(AB11:AI11)) -> 13 | AK11: =IF(C11="","",IF(AJ11>=14,"A",IF(AJ11>=10,"B","C"))) -> B | AL11: =IFERROR(IF(OR(Y11="",Z11="",AA11=""),"",IF(F11="Short",IF(Z11<=Y11,"",(Y11-AA11)/(Z11-Y11)),IF(Y11<=Z11,"",(AA11-Y11)/(Y11-Z11)))),"") -> 3.0060241 | AM11: =IF(OR(Y11="",Z11="",N(Y11)=N(Z11)),"",IF(OR(AND(F11="Short",Z11<Y11),AND(NOT(F11="Short"),Z11>Y11)),"stop on wrong side",ABS(Y11-Z11))) -> 8.3 | AN11: =IFERROR(IF(OR(NOT(ISNUMBER(AM11)),$C$6=""),"",ROUNDDOWN($C$6*$C$7/AM11,2)),"") -> 0.05 | AO11: =IFERROR(IF(AN11="","",AN11*Y11),"") -> 7.45 | AP11: Dropped | AS11: =IFERROR(IF(OR(AR11="",Y11="",AQ11=""),"",IF(F11="Short",1-AR11/Y11,AR11/Y11-1)),"") | AT11: =IF(AQ11="","",IF(ISNUMBER($C$4),$C$4,TODAY())-AQ11) | AU11: =IF(C11="","",IF(AP11="Open position",IF(IF(F11="Short",AND(ISNUMBER(AR11),ISNUMBER(Z11),AR11>=Z11),AND(ISNUMBER(AR11),ISNUMBER(Z11),AR11<=Z11)),IF(F11="Short","COVER — stop hit (buy back)","SELL — stop hit"),IF(IF(F11="Short",AND(ISNUMBER(AR11),ISNUMBER(AA11),AR11<=AA11),AND(ISNUMBER(AR11),ISNUMBER(AA11),AR11>=AA11)),"TAKE PROFIT — target hit",IF(AND(ISNUMBER(AT11),AT11>182),IF(F11="Short","COVER — 6-month time limit","SELL — 6-month time limit"),IF(AND(ISNUMBER(AT11),AT11>42,ISNUMBER(AS11),AS11<0.02),"REVIEW — no progress after 6 weeks",IF(IF(F11="Short",AND(L11<>"",N(L11)>0),AND(L11<>"",N(L11)<0)),IF(F11="Short","REVIEW — back above 50-day avg","REVIEW — below 50-day avg"),"HOLD"))))),IF(OR(AP11="Closed",AP11="Dropped"),"Closed",IF(AK11="A",IF(F11="Short","Run Technical Review — SHORT entry","Run Technical Review — LONG entry"),IF(AK11="B","Watch — wait for setup","Drop or re-check next week"))))) -> Closed | AV11: Trigger: Break above the 1 Oct high (148.57) and the 50-day (146.5). Long entry 149.00, stop 140.70 (2×ATR), target 173.95 (R:R 3.0). LRC Work-sheet 6-m rating: BUY (6-m target ~$163, +13%). BUY rating + technical clearance (staged entry) in the LRC Work-sheet. Fundamentals and trend agree. First profit-taking at the 6-m target ~$163; full target in the bull-case zone. Data: Yahoo Finance OHLCV to 2 Oct 2026 (SMA20, ATR14, rel. volume computed); SMA50/200, RSI, short float, earnings date: stockanalysis.com; EPS growth this yr = consensus current FY (adjusted). — P. Nkuna || 14 Oct update: trigger 149.00 was hit (~8 Oct) but the trade was NOT entered (not in the 14 Oct broker export). Price now $158.11 = our 6-m target; Work-sheet re-rated BUY → HOLD (target ~$157, −1%). No new entry; re-add below ~$146. — P. Nkuna | AX11: =IF(AND(C11<>"",A11=$C$4,ISNUMBER(AJ11)),AJ11+ROW()/100000,"")
A12: 46298 | B12: US | C12: WAB | D12: Westinghouse Air Brake Technologies Corporation (Wabtec) | E12: Industrials | F12: Short | G12: 287.54 | H12: 48.57 | I12: 769100 | J12: =IF(OR(G12="",I12=""),"",G12*I12/1000000) -> 221.14701 | K12: 0.0102 | L12: -0.0105 | M12: 0.0996 | N12: 51.1 | O12: 0.0967 | P12: 0.1324 | Q12: -0.0623 | R12: 0.5454 | S12: 1.19 | T12: 0.2114 | U12: 0.0215 | V12: 46316 | W12: 5.73 | X12: SHORT: Breakdown from base | Y12: 272.9 | Z12: 284.35 | AA12: 238.5 | AB12: =IF(C12="","",IF(F12="Short",(AND(M12<>"",N(M12)<0))+(AND(L12<>"",N(L12)<0))+(AND(K12<>"",N(K12)<0))+AND(L12<>"",M12<>"",N(M12)<N(L12)),(N(M12)>0)+(N(L12)>0)+(N(K12)>0)+AND(L12<>"",M12<>"",N(M12)>N(L12)))) -> 1 | AC12: =IF(C12="","",IF(F12="Short",IF(N12="",0,IF(AND(N12>=30,N12<=50),2,IF(OR(AND(N12>=25,N12<30),AND(N12>50,N12<=60)),1,0)))+IF(P12="",0,IF(AND(IF(B12="JSE",$L$5,$L$4)<>"",P12<IF(B12="JSE",$L$5,$L$4)),2,IF(P12<0,1,0))),IF(N12="",0,IF(AND(N12>=50,N12<=70),2,IF(OR(AND(N12>=40,N12<50),AND(N12>70,N12<=75)),1,0)))+IF(P12="",0,IF(AND(IF(B12="JSE",$L$5,$L$4)<>"",P12>IF(B12="JSE",$L$5,$L$4)),2,IF(P12>0,1,0))))) -> 3 | AD12: =IF(C12="","",IF(F12="Short",IF(R12="",0,IF(R12<=0.1,2,IF(R12<=0.25,1,0))),IF(Q12="",0,IF(Q12>=-0.1,2,IF(Q12>=-0.25,1,0))))) -> 0 | AE12: =IF(C12="","",IF(J12="",0,IF(J12>=IF(B12="JSE",$L$7,$L$6),2,IF(J12>=IF(B12="JSE",$L$7,$L$6)/4,1,0)))) -> 2 | AF12: =IF(C12="","",IF(F12="Short",AND(T12<>"",N(T12)<0),N(T12)>0)+(N(S12)>=1.5)) -> 0 | AG12: =IF(C12="","",IF(AL12="",0,IF(AL12>=3,4,IF(AL12>=2,2,0)))) -> 4 | AH12: =IF(C12="","",IF(AND(ISNUMBER(V12),ISNUMBER(A12),V12>=A12,V12-A12<=14),-2,0)) -> 0 | AI12: =IF(C12="","",IF(AND(F12="Short",N(U12)>=0.2),-1,0)) -> 0 | AJ12: =IF(C12="","",SUM(AB12:AI12)) -> 10 | AK12: =IF(C12="","",IF(AJ12>=14,"A",IF(AJ12>=10,"B","C"))) -> B | AL12: =IFERROR(IF(OR(Y12="",Z12="",AA12=""),"",IF(F12="Short",IF(Z12<=Y12,"",(Y12-AA12)/(Z12-Y12)),IF(Y12<=Z12,"",(AA12-Y12)/(Y12-Z12)))),"") -> 3.0043668 | AM12: =IF(OR(Y12="",Z12="",N(Y12)=N(Z12)),"",IF(OR(AND(F12="Short",Z12<Y12),AND(NOT(F12="Short"),Z12>Y12)),"stop on wrong side",ABS(Y12-Z12))) -> 11.45 | AN12: =IFERROR(IF(OR(NOT(ISNUMBER(AM12)),$C$6=""),"",ROUNDDOWN($C$6*$C$7/AM12,2)),"") -> 0.03 | AO12: =IFERROR(IF(AN12="","",AN12*Y12),"") -> 8.187 | AP12: Watch | AS12: =IFERROR(IF(OR(AR12="",Y12="",AQ12=""),"",IF(F12="Short",1-AR12/Y12,AR12/Y12-1)),"") | AT12: =IF(AQ12="","",IF(ISNUMBER($C$4),$C$4,TODAY())-AQ12) | AU12: =IF(C12="","",IF(AP12="Open position",IF(IF(F12="Short",AND(ISNUMBER(AR12),ISNUMBER(Z12),AR12>=Z12),AND(ISNUMBER(AR12),ISNUMBER(Z12),AR12<=Z12)),IF(F12="Short","COVER — stop hit (buy back)","SELL — stop hit"),IF(IF(F12="Short",AND(ISNUMBER(AR12),ISNUMBER(AA12),AR12<=AA12),AND(ISNUMBER(AR12),ISNUMBER(AA12),AR12>=AA12)),"TAKE PROFIT — target hit",IF(AND(ISNUMBER(AT12),AT12>182),IF(F12="Short","COVER — 6-month time limit","SELL — 6-month time limit"),IF(AND(ISNUMBER(AT12),AT12>42,ISNUMBER(AS12),AS12<0.02),"REVIEW — no progress after 6 weeks",IF(IF(F12="Short",AND(L12<>"",N(L12)>0),AND(L12<>"",N(L12)<0)),IF(F12="Short","REVIEW — back above 50-day avg","REVIEW — below 50-day avg"),"HOLD"))))),IF(OR(AP12="Closed",AP12="Dropped"),"Closed",IF(AK12="A",IF(F12="Short","Run Technical Review — SHORT entry","Run Technical Review — LONG entry"),IF(AK12="B","Watch — wait for setup","Drop or re-check next week"))))) -> Watch — wait for setup | AV12: Trigger: Sell stop below the 16 Sep swing low (273.01) — confirms the uptrend has broken. Short entry 272.90, stop 284.35 (2×ATR), target 238.50 (R:R 3.0). LRC Work-sheet 6-m rating: SELL (~$242, -16%). SELL rating + technical clearance in the LRC Work-sheet. Short only on a confirmed breakdown: the stock is still in an uptrend (above 200-day), so the trend score is low until it breaks. Target ~238 ≈ fundamental target $242. Results 21 Oct. Data: Yahoo Finance OHLCV to 2 Oct 2026 (SMA20, ATR14, rel. volume computed); SMA50/200, RSI, short float, earnings date: stockanalysis.com; EPS growth this yr = consensus current FY (adjusted). — P. Nkuna || 14 Oct update: still SELL (6-m target ~$248, −13%) + technically cleared. Price $286.51 is 5% above the 272.90 trigger — not triggered. Results 21 Oct inside 14 days: no new short before the print. Keep last week's levels; re-plan after results. — P. Nkuna | AX12: =IF(AND(C12<>"",A12=$C$4,ISNUMBER(AJ12)),AJ12+ROW()/100000,"")
A13: 46298 | B13: US | C13: ANET | D13: Arista Networks, Inc. | E13: Technology | F13: Short | G13: 207.35 | H13: 260.9 | I13: 4650000 | J13: =IF(OR(G13="",I13=""),"",G13*I13/1000000) -> 964.1775 | K13: 0.0376 | L13: 0.0684 | M13: 0.3015 | N13: 59.5 | O13: 0.296 | P13: 0.6368 | Q13: -0.0351 | R13: 0.8106 | S13: 0.89 | T13: 0.3799 | U13: 0.0126 | V13: 46329 | W13: 6.34 | X13: SHORT: Breakdown from base | Y13: 186 | Z13: 198.67 | AA13: 147.99 | AB13: =IF(C13="","",IF(F13="Short",(AND(M13<>"",N(M13)<0))+(AND(L13<>"",N(L13)<0))+(AND(K13<>"",N(K13)<0))+AND(L13<>"",M13<>"",N(M13)<N(L13)),(N(M13)>0)+(N(L13)>0)+(N(K13)>0)+AND(L13<>"",M13<>"",N(M13)>N(L13)))) -> 0 | AC13: =IF(C13="","",IF(F13="Short",IF(N13="",0,IF(AND(N13>=30,N13<=50),2,IF(OR(AND(N13>=25,N13<30),AND(N13>50,N13<=60)),1,0)))+IF(P13="",0,IF(AND(IF(B13="JSE",$L$5,$L$4)<>"",P13<IF(B13="JSE",$L$5,$L$4)),2,IF(P13<0,1,0))),IF(N13="",0,IF(AND(N13>=50,N13<=70),2,IF(OR(AND(N13>=40,N13<50),AND(N13>70,N13<=75)),1,0)))+IF(P13="",0,IF(AND(IF(B13="JSE",$L$5,$L$4)<>"",P13>IF(B13="JSE",$L$5,$L$4)),2,IF(P13>0,1,0))))) -> 1 | AD13: =IF(C13="","",IF(F13="Short",IF(R13="",0,IF(R13<=0.1,2,IF(R13<=0.25,1,0))),IF(Q13="",0,IF(Q13>=-0.1,2,IF(Q13>=-0.25,1,0))))) -> 0 | AE13: =IF(C13="","",IF(J13="",0,IF(J13>=IF(B13="JSE",$L$7,$L$6),2,IF(J13>=IF(B13="JSE",$L$7,$L$6)/4,1,0)))) -> 2 | AF13: =IF(C13="","",IF(F13="Short",AND(T13<>"",N(T13)<0),N(T13)>0)+(N(S13)>=1.5)) -> 0 | AG13: =IF(C13="","",IF(AL13="",0,IF(AL13>=3,4,IF(AL13>=2,2,0)))) -> 4 | AH13: =IF(C13="","",IF(AND(ISNUMBER(V13),ISNUMBER(A13),V13>=A13,V13-A13<=14),-2,0)) -> 0 | AI13: =IF(C13="","",IF(AND(F13="Short",N(U13)>=0.2),-1,0)) -> 0 | AJ13: =IF(C13="","",SUM(AB13:AI13)) -> 7 | AK13: =IF(C13="","",IF(AJ13>=14,"A",IF(AJ13>=10,"B","C"))) -> C | AL13: =IFERROR(IF(OR(Y13="",Z13="",AA13=""),"",IF(F13="Short",IF(Z13<=Y13,"",(Y13-AA13)/(Z13-Y13)),IF(Y13<=Z13,"",(AA13-Y13)/(Y13-Z13)))),"") -> 3 | AM13: =IF(OR(Y13="",Z13="",N(Y13)=N(Z13)),"",IF(OR(AND(F13="Short",Z13<Y13),AND(NOT(F13="Short"),Z13>Y13)),"stop on wrong side",ABS(Y13-Z13))) -> 12.67 | AN13: =IFERROR(IF(OR(NOT(ISNUMBER(AM13)),$C$6=""),"",ROUNDDOWN($C$6*$C$7/AM13,2)),"") -> 0.03 | AO13: =IFERROR(IF(AN13="","",AN13*Y13),"") -> 5.58 | AP13: Dropped | AS13: =IFERROR(IF(OR(AR13="",Y13="",AQ13=""),"",IF(F13="Short",1-AR13/Y13,AR13/Y13-1)),"") | AT13: =IF(AQ13="","",IF(ISNUMBER($C$4),$C$4,TODAY())-AQ13) | AU13: =IF(C13="","",IF(AP13="Open position",IF(IF(F13="Short",AND(ISNUMBER(AR13),ISNUMBER(Z13),AR13>=Z13),AND(ISNUMBER(AR13),ISNUMBER(Z13),AR13<=Z13)),IF(F13="Short","COVER — stop hit (buy back)","SELL — stop hit"),IF(IF(F13="Short",AND(ISNUMBER(AR13),ISNUMBER(AA13),AR13<=AA13),AND(ISNUMBER(AR13),ISNUMBER(AA13),AR13>=AA13)),"TAKE PROFIT — target hit",IF(AND(ISNUMBER(AT13),AT13>182),IF(F13="Short","COVER — 6-month time limit","SELL — 6-month time limit"),IF(AND(ISNUMBER(AT13),AT13>42,ISNUMBER(AS13),AS13<0.02),"REVIEW — no progress after 6 weeks",IF(IF(F13="Short",AND(L13<>"",N(L13)>0),AND(L13<>"",N(L13)<0)),IF(F13="Short","REVIEW — back above 50-day avg","REVIEW — below 50-day avg"),"HOLD"))))),IF(OR(AP13="Closed",AP13="Dropped"),"Closed",IF(AK13="A",IF(F13="Short","Run Technical Review — SHORT entry","Run Technical Review — LONG entry"),IF(AK13="B","Watch — wait for setup","Drop or re-check next week"))))) -> Closed | AV13: Trigger: Sell stop below the 14 Sep swing low (186.11) and the 50-day (194). Short entry 186.00, stop 198.67 (2×ATR), target 147.99 (R:R 3.0). LRC Work-sheet 6-m rating: SELL (~$144, -30%). SELL rating + technical clearance in the LRC Work-sheet. Short only on a confirmed breakdown below 186; today it is the strongest trend on our list (+64% in 6 months) — do NOT short strength. Target ~148 ≈ fundamental target $144. High beta (1.6): small size. Data: Yahoo Finance OHLCV to 2 Oct 2026 (SMA20, ATR14, rel. volume computed); SMA50/200, RSI, short float, earnings date: stockanalysis.com; EPS growth this yr = consensus current FY (adjusted). — P. Nkuna || 14 Oct update: replaced by a new ANET row this week (trigger 197.40, stop 211.02, target 156.54). Old trigger 186 not hit. — P. Nkuna | AX13: =IF(AND(C13<>"",A13=$C$4,ISNUMBER(AJ13)),AJ13+ROW()/100000,"")
A14: 46312 | B14: US | C14: NVDA | D14: NVIDIA Corporation | E14: Technology | F14: Long | G14: 228.52 | H14: 5520 | I14: 105231900 | J14: =IF(OR(G14="",I14=""),"",G14*I14/1000000) -> 24047.594 | K14: 0.0009 | L14: 0.0246 | M14: 0.1283 | N14: 52 | P14: 0.2071 | Q14: -0.061 | R14: 0.3911 | S14: 0.8 | T14: 0.9523 | U14: 0.0134 | V14: 46344 | W14: 5.31 | X14: LONG: Pullback to 20/50-day avg | Y14: 229.3 | Z14: 218.68 | AA14: 261.16 | AB14: =IF(C14="","",IF(F14="Short",(AND(M14<>"",N(M14)<0))+(AND(L14<>"",N(L14)<0))+(AND(K14<>"",N(K14)<0))+AND(L14<>"",M14<>"",N(M14)<N(L14)),(N(M14)>0)+(N(L14)>0)+(N(K14)>0)+AND(L14<>"",M14<>"",N(M14)>N(L14)))) -> 4 | AC14: =IF(C14="","",IF(F14="Short",IF(N14="",0,IF(AND(N14>=30,N14<=50),2,IF(OR(AND(N14>=25,N14<30),AND(N14>50,N14<=60)),1,0)))+IF(P14="",0,IF(AND(IF(B14="JSE",$L$5,$L$4)<>"",P14<IF(B14="JSE",$L$5,$L$4)),2,IF(P14<0,1,0))),IF(N14="",0,IF(AND(N14>=50,N14<=70),2,IF(OR(AND(N14>=40,N14<50),AND(N14>70,N14<=75)),1,0)))+IF(P14="",0,IF(AND(IF(B14="JSE",$L$5,$L$4)<>"",P14>IF(B14="JSE",$L$5,$L$4)),2,IF(P14>0,1,0))))) -> 4 | AD14: =IF(C14="","",IF(F14="Short",IF(R14="",0,IF(R14<=0.1,2,IF(R14<=0.25,1,0))),IF(Q14="",0,IF(Q14>=-0.1,2,IF(Q14>=-0.25,1,0))))) -> 2 | AE14: =IF(C14="","",IF(J14="",0,IF(J14>=IF(B14="JSE",$L$7,$L$6),2,IF(J14>=IF(B14="JSE",$L$7,$L$6)/4,1,0)))) -> 2 | AF14: =IF(C14="","",IF(F14="Short",AND(T14<>"",N(T14)<0),N(T14)>0)+(N(S14)>=1.5)) -> 1 | AG14: =IF(C14="","",IF(AL14="",0,IF(AL14>=3,4,IF(AL14>=2,2,0)))) -> 4 | AH14: =IF(C14="","",IF(AND(ISNUMBER(V14),ISNUMBER(A14),V14>=A14,V14-A14<=14),-2,0)) -> 0 | AI14: =IF(C14="","",IF(AND(F14="Short",N(U14)>=0.2),-1,0)) -> 0 | AJ14: =IF(C14="","",SUM(AB14:AI14)) -> 17 | AK14: =IF(C14="","",IF(AJ14>=14,"A",IF(AJ14>=10,"B","C"))) -> A | AL14: =IFERROR(IF(OR(Y14="",Z14="",AA14=""),"",IF(F14="Short",IF(Z14<=Y14,"",(Y14-AA14)/(Z14-Y14)),IF(Y14<=Z14,"",(AA14-Y14)/(Y14-Z14)))),"") -> 3 | AM14: =IF(OR(Y14="",Z14="",N(Y14)=N(Z14)),"",IF(OR(AND(F14="Short",Z14<Y14),AND(NOT(F14="Short"),Z14>Y14)),"stop on wrong side",ABS(Y14-Z14))) -> 10.62 | AN14: =IFERROR(IF(OR(NOT(ISNUMBER(AM14)),$C$6=""),"",ROUNDDOWN($C$6*$C$7/AM14,2)),"") -> 0.04 | AO14: =IFERROR(IF(AN14="","",AN14*Y14),"") -> 9.172 | AP14: Entry setup | AS14: =IFERROR(IF(OR(AR14="",Y14="",AQ14=""),"",IF(F14="Short",1-AR14/Y14,AR14/Y14-1)),"") | AT14: =IF(AQ14="","",IF(ISNUMBER($C$4),$C$4,TODAY())-AQ14) | AU14: =IF(C14="","",IF(AP14="Open position",IF(IF(F14="Short",AND(ISNUMBER(AR14),ISNUMBER(Z14),AR14>=Z14),AND(ISNUMBER(AR14),ISNUMBER(Z14),AR14<=Z14)),IF(F14="Short","COVER — stop hit (buy back)","SELL — stop hit"),IF(IF(F14="Short",AND(ISNUMBER(AR14),ISNUMBER(AA14),AR14<=AA14),AND(ISNUMBER(AR14),ISNUMBER(AA14),AR14>=AA14)),"TAKE PROFIT — target hit",IF(AND(ISNUMBER(AT14),AT14>182),IF(F14="Short","COVER — 6-month time limit","SELL — 6-month time limit"),IF(AND(ISNUMBER(AT14),AT14>42,ISNUMBER(AS14),AS14<0.02),"REVIEW — no progress after 6 weeks",IF(IF(F14="Short",AND(L14<>"",N(L14)>0),AND(L14<>"",N(L14)<0)),IF(F14="Short","REVIEW — back above 50-day avg","REVIEW — below 50-day avg"),"HOLD"))))),IF(OR(AP14="Closed",AP14="Dropped"),"Closed",IF(AK14="A",IF(F14="Short","Run Technical Review — SHORT entry","Run Technical Review — LONG entry"),IF(AK14="B","Watch — wait for setup","Drop or re-check next week"))))) -> Run Technical Review — LONG entry | AV14: Trigger: Buy stop above the 12-13 Oct highs (228.86); price sits on the 20-day (228.3) just above the 50-day (223.0). Long entry 229.30, stop 218.68 (2×ATR 5.31), target 261.16 (3R). LRC Work-sheet 14 Oct: BUY (6-m target ~$262.56, +15%; score 3.8/5; technical: CLEARED — STAGED ENTRY). Only name this week with BUY + technical clearance (CLEARED — staged entry). Fundamentals and trend agree. Target ≈ 6-m fundamental target. Results 18 Nov (outside 14 days). Data 13 Oct close: stockanalysis statistics + daily history to 13 Oct (SMA20/ATR14 computed); Perf Half vs ~13 Apr close; EPS growth this yr = consensus current FY (adjusted). Perf Quarter n/f (history page holds 50 sessions). Finviz itself blocked for us — same filters applied manually. — P. Nkuna | AX14: =IF(AND(C14<>"",A14=$C$4,ISNUMBER(AJ14)),AJ14+ROW()/100000,"")
A15: 46312 | B15: US | C15: INTU | D15: Intuit Inc. | E15: Technology | F15: Long | G15: 301.45 | H15: 80.56 | I15: 3875886 | J15: =IF(OR(G15="",I15=""),"",G15*I15/1000000) -> 1168.3858 | K15: 0.0335 | L15: -0.0614 | M15: -0.2081 | N15: 49.9 | P15: -0.184 | Q15: -0.5626 | R15: 0.1923 | S15: 0.95 | T15: -0.0133 | U15: 0.0279 | V15: 46345 | W15: 10.41 | X15: LONG: Reversal (higher low) | Y15: 322 | Z15: 301.18 | AA15: 384.46 | AB15: =IF(C15="","",IF(F15="Short",(AND(M15<>"",N(M15)<0))+(AND(L15<>"",N(L15)<0))+(AND(K15<>"",N(K15)<0))+AND(L15<>"",M15<>"",N(M15)<N(L15)),(N(M15)>0)+(N(L15)>0)+(N(K15)>0)+AND(L15<>"",M15<>"",N(M15)>N(L15)))) -> 1 | AC15: =IF(C15="","",IF(F15="Short",IF(N15="",0,IF(AND(N15>=30,N15<=50),2,IF(OR(AND(N15>=25,N15<30),AND(N15>50,N15<=60)),1,0)))+IF(P15="",0,IF(AND(IF(B15="JSE",$L$5,$L$4)<>"",P15<IF(B15="JSE",$L$5,$L$4)),2,IF(P15<0,1,0))),IF(N15="",0,IF(AND(N15>=50,N15<=70),2,IF(OR(AND(N15>=40,N15<50),AND(N15>70,N15<=75)),1,0)))+IF(P15="",0,IF(AND(IF(B15="JSE",$L$5,$L$4)<>"",P15>IF(B15="JSE",$L$5,$L$4)),2,IF(P15>0,1,0))))) -> 1 | AD15: =IF(C15="","",IF(F15="Short",IF(R15="",0,IF(R15<=0.1,2,IF(R15<=0.25,1,0))),IF(Q15="",0,IF(Q15>=-0.1,2,IF(Q15>=-0.25,1,0))))) -> 0 | AE15: =IF(C15="","",IF(J15="",0,IF(J15>=IF(B15="JSE",$L$7,$L$6),2,IF(J15>=IF(B15="JSE",$L$7,$L$6)/4,1,0)))) -> 2 | AF15: =IF(C15="","",IF(F15="Short",AND(T15<>"",N(T15)<0),N(T15)>0)+(N(S15)>=1.5)) -> 0 | AG15: =IF(C15="","",IF(AL15="",0,IF(AL15>=3,4,IF(AL15>=2,2,0)))) -> 4 | AH15: =IF(C15="","",IF(AND(ISNUMBER(V15),ISNUMBER(A15),V15>=A15,V15-A15<=14),-2,0)) -> 0 | AI15: =IF(C15="","",IF(AND(F15="Short",N(U15)>=0.2),-1,0)) -> 0 | AJ15: =IF(C15="","",SUM(AB15:AI15)) -> 8 | AK15: =IF(C15="","",IF(AJ15>=14,"A",IF(AJ15>=10,"B","C"))) -> C | AL15: =IFERROR(IF(OR(Y15="",Z15="",AA15=""),"",IF(F15="Short",IF(Z15<=Y15,"",(Y15-AA15)/(Z15-Y15)),IF(Y15<=Z15,"",(AA15-Y15)/(Y15-Z15)))),"") -> 3 | AM15: =IF(OR(Y15="",Z15="",N(Y15)=N(Z15)),"",IF(OR(AND(F15="Short",Z15<Y15),AND(NOT(F15="Short"),Z15>Y15)),"stop on wrong side",ABS(Y15-Z15))) -> 20.82 | AN15: =IFERROR(IF(OR(NOT(ISNUMBER(AM15)),$C$6=""),"",ROUNDDOWN($C$6*$C$7/AM15,2)),"") -> 0.02 | AO15: =IFERROR(IF(AN15="","",AN15*Y15),"") -> 6.44 | AP15: Watch | AS15: =IFERROR(IF(OR(AR15="",Y15="",AQ15=""),"",IF(F15="Short",1-AR15/Y15,AR15/Y15-1)),"") | AT15: =IF(AQ15="","",IF(ISNUMBER($C$4),$C$4,TODAY())-AQ15) | AU15: =IF(C15="","",IF(AP15="Open position",IF(IF(F15="Short",AND(ISNUMBER(AR15),ISNUMBER(Z15),AR15>=Z15),AND(ISNUMBER(AR15),ISNUMBER(Z15),AR15<=Z15)),IF(F15="Short","COVER — stop hit (buy back)","SELL — stop hit"),IF(IF(F15="Short",AND(ISNUMBER(AR15),ISNUMBER(AA15),AR15<=AA15),AND(ISNUMBER(AR15),ISNUMBER(AA15),AR15>=AA15)),"TAKE PROFIT — target hit",IF(AND(ISNUMBER(AT15),AT15>182),IF(F15="Short","COVER — 6-month time limit","SELL — 6-month time limit"),IF(AND(ISNUMBER(AT15),AT15>42,ISNUMBER(AS15),AS15<0.02),"REVIEW — no progress after 6 weeks",IF(IF(F15="Short",AND(L15<>"",N(L15)>0),AND(L15<>"",N(L15)<0)),IF(F15="Short","REVIEW — back above 50-day avg","REVIEW — below 50-day avg"),"HOLD"))))),IF(OR(AP15="Closed",AP15="Dropped"),"Closed",IF(AK15="A",IF(F15="Short","Run Technical Review — SHORT entry","Run Technical Review — LONG entry"),IF(AK15="B","Watch — wait for setup","Drop or re-check next week"))))) -> Drop or re-check next week | AV15: Trigger: Only on a close back above the 50-day average (321.16) — today the trend is DOWN (below 50/200-day). Long entry 322.00, stop 301.18 (2×ATR 10.41), target 384.46 (3R). LRC Work-sheet 14 Oct: BUY (6-m target ~$426.00, +41%; score 4.0/5; technical: NOT CLEARED — score below 70%). BUY on fundamentals (+41%) but NOT technically cleared (downtrend). Watch only — do not trade until the Technical Review is re-ticked and cleared above the 50-day. Results 19 Nov. Data 13 Oct close: stockanalysis statistics/history (Finviz-preset replica, short screen); Perf Half vs ~13 Apr close; EPS growth this yr = consensus current FY (adjusted). Perf Quarter n/f (history page holds 50 sessions). Finviz itself blocked for us — same filters applied manually. — P. Nkuna | AX15: =IF(AND(C15<>"",A15=$C$4,ISNUMBER(AJ15)),AJ15+ROW()/100000,"")
A16: 46312 | B16: US | C16: DECK | D16: Deckers Outdoor Corporation | E16: Consumer Discretionary | F16: Long | G16: 84.02 | H16: 11.44 | I16: 3159200 | J16: =IF(OR(G16="",I16=""),"",G16*I16/1000000) -> 265.43598 | K16: 0.0496 | L16: -0.0157 | M16: -0.1649 | N16: 56.2 | P16: -0.223 | Q16: -0.3129 | R16: 0.0883 | S16: 0.95 | T16: 0.0733 | U16: 0.0877 | V16: 46317 | W16: 1.96 | X16: LONG: Reversal (higher low) | Y16: 86.3 | Z16: 82.38 | AA16: 98.06 | AB16: =IF(C16="","",IF(F16="Short",(AND(M16<>"",N(M16)<0))+(AND(L16<>"",N(L16)<0))+(AND(K16<>"",N(K16)<0))+AND(L16<>"",M16<>"",N(M16)<N(L16)),(N(M16)>0)+(N(L16)>0)+(N(K16)>0)+AND(L16<>"",M16<>"",N(M16)>N(L16)))) -> 1 | AC16: =IF(C16="","",IF(F16="Short",IF(N16="",0,IF(AND(N16>=30,N16<=50),2,IF(OR(AND(N16>=25,N16<30),AND(N16>50,N16<=60)),1,0)))+IF(P16="",0,IF(AND(IF(B16="JSE",$L$5,$L$4)<>"",P16<IF(B16="JSE",$L$5,$L$4)),2,IF(P16<0,1,0))),IF(N16="",0,IF(AND(N16>=50,N16<=70),2,IF(OR(AND(N16>=40,N16<50),AND(N16>70,N16<=75)),1,0)))+IF(P16="",0,IF(AND(IF(B16="JSE",$L$5,$L$4)<>"",P16>IF(B16="JSE",$L$5,$L$4)),2,IF(P16>0,1,0))))) -> 2 | AD16: =IF(C16="","",IF(F16="Short",IF(R16="",0,IF(R16<=0.1,2,IF(R16<=0.25,1,0))),IF(Q16="",0,IF(Q16>=-0.1,2,IF(Q16>=-0.25,1,0))))) -> 0 | AE16: =IF(C16="","",IF(J16="",0,IF(J16>=IF(B16="JSE",$L$7,$L$6),2,IF(J16>=IF(B16="JSE",$L$7,$L$6)/4,1,0)))) -> 2 | AF16: =IF(C16="","",IF(F16="Short",AND(T16<>"",N(T16)<0),N(T16)>0)+(N(S16)>=1.5)) -> 1 | AG16: =IF(C16="","",IF(AL16="",0,IF(AL16>=3,4,IF(AL16>=2,2,0)))) -> 4 | AH16: =IF(C16="","",IF(AND(ISNUMBER(V16),ISNUMBER(A16),V16>=A16,V16-A16<=14),-2,0)) -> -2 | AI16: =IF(C16="","",IF(AND(F16="Short",N(U16)>=0.2),-1,0)) -> 0 | AJ16: =IF(C16="","",SUM(AB16:AI16)) -> 8 | AK16: =IF(C16="","",IF(AJ16>=14,"A",IF(AJ16>=10,"B","C"))) -> C | AL16: =IFERROR(IF(OR(Y16="",Z16="",AA16=""),"",IF(F16="Short",IF(Z16<=Y16,"",(Y16-AA16)/(Z16-Y16)),IF(Y16<=Z16,"",(AA16-Y16)/(Y16-Z16)))),"") -> 3 | AM16: =IF(OR(Y16="",Z16="",N(Y16)=N(Z16)),"",IF(OR(AND(F16="Short",Z16<Y16),AND(NOT(F16="Short"),Z16>Y16)),"stop on wrong side",ABS(Y16-Z16))) -> 3.92 | AN16: =IFERROR(IF(OR(NOT(ISNUMBER(AM16)),$C$6=""),"",ROUNDDOWN($C$6*$C$7/AM16,2)),"") -> 0.11 | AO16: =IFERROR(IF(AN16="","",AN16*Y16),"") -> 9.493 | AP16: Watch | AS16: =IFERROR(IF(OR(AR16="",Y16="",AQ16=""),"",IF(F16="Short",1-AR16/Y16,AR16/Y16-1)),"") | AT16: =IF(AQ16="","",IF(ISNUMBER($C$4),$C$4,TODAY())-AQ16) | AU16: =IF(C16="","",IF(AP16="Open position",IF(IF(F16="Short",AND(ISNUMBER(AR16),ISNUMBER(Z16),AR16>=Z16),AND(ISNUMBER(AR16),ISNUMBER(Z16),AR16<=Z16)),IF(F16="Short","COVER — stop hit (buy back)","SELL — stop hit"),IF(IF(F16="Short",AND(ISNUMBER(AR16),ISNUMBER(AA16),AR16<=AA16),AND(ISNUMBER(AR16),ISNUMBER(AA16),AR16>=AA16)),"TAKE PROFIT — target hit",IF(AND(ISNUMBER(AT16),AT16>182),IF(F16="Short","COVER — 6-month time limit","SELL — 6-month time limit"),IF(AND(ISNUMBER(AT16),AT16>42,ISNUMBER(AS16),AS16<0.02),"REVIEW — no progress after 6 weeks",IF(IF(F16="Short",AND(L16<>"",N(L16)>0),AND(L16<>"",N(L16)<0)),IF(F16="Short","REVIEW — back above 50-day avg","REVIEW — below 50-day avg"),"HOLD"))))),IF(OR(AP16="Closed",AP16="Dropped"),"Closed",IF(AK16="A",IF(F16="Short","Run Technical Review — SHORT entry","Run Technical Review — LONG entry"),IF(AK16="B","Watch — wait for setup","Drop or re-check next week"))))) -> Drop or re-check next week | AV16: Trigger: Above the 15-day high (86.25) and the 50-day (85.36); results 22 Oct — wait for the print. Long entry 86.30, stop 82.38 (2×ATR 1.96), target 98.06 (3R). LRC Work-sheet 14 Oct: BUY (6-m target ~$103.00, +23%; score 3.8/5; technical: NOT CLEARED — score below 70%). BUY on fundamentals (+23%) but NOT technically cleared (downtrend). Results 22 Oct inside 14 days (event risk). Watch only until cleared. Data 13 Oct close: stockanalysis statistics + daily history to 13 Oct (SMA20/ATR14 computed); Perf Half vs ~13 Apr close; EPS growth this yr = consensus current FY (adjusted). Perf Quarter n/f (history page holds 50 sessions). Finviz itself blocked for us — same filters applied manually. — P. Nkuna | AX16: =IF(AND(C16<>"",A16=$C$4,ISNUMBER(AJ16)),AJ16+ROW()/100000,"")
A17: 46312 | B17: US | C17: NKE | D17: NIKE, Inc. | E17: Consumer Discretionary | F17: Short | G17: 35.33 | H17: 52.48 | I17: 45217604 | J17: =IF(OR(G17="",I17=""),"",G17*I17/1000000) -> 1597.5379 | K17: -0.0011 | L17: -0.0671 | M17: -0.2604 | N17: 43.7 | P17: -0.1604 | Q17: -0.4984 | R17: 0.1051 | S17: 0.67 | T17: -0.1642 | U17: 0.0842 | W17: 1.13 | X17: SHORT: Downtrend continuation | Y17: 34.9 | Z17: 37.16 | AA17: 28.12 | AB17: =IF(C17="","",IF(F17="Short",(AND(M17<>"",N(M17)<0))+(AND(L17<>"",N(L17)<0))+(AND(K17<>"",N(K17)<0))+AND(L17<>"",M17<>"",N(M17)<N(L17)),(N(M17)>0)+(N(L17)>0)+(N(K17)>0)+AND(L17<>"",M17<>"",N(M17)>N(L17)))) -> 4 | AC17: =IF(C17="","",IF(F17="Short",IF(N17="",0,IF(AND(N17>=30,N17<=50),2,IF(OR(AND(N17>=25,N17<30),AND(N17>50,N17<=60)),1,0)))+IF(P17="",0,IF(AND(IF(B17="JSE",$L$5,$L$4)<>"",P17<IF(B17="JSE",$L$5,$L$4)),2,IF(P17<0,1,0))),IF(N17="",0,IF(AND(N17>=50,N17<=70),2,IF(OR(AND(N17>=40,N17<50),AND(N17>70,N17<=75)),1,0)))+IF(P17="",0,IF(AND(IF(B17="JSE",$L$5,$L$4)<>"",P17>IF(B17="JSE",$L$5,$L$4)),2,IF(P17>0,1,0))))) -> 4 | AD17: =IF(C17="","",IF(F17="Short",IF(R17="",0,IF(R17<=0.1,2,IF(R17<=0.25,1,0))),IF(Q17="",0,IF(Q17>=-0.1,2,IF(Q17>=-0.25,1,0))))) -> 1 | AE17: =IF(C17="","",IF(J17="",0,IF(J17>=IF(B17="JSE",$L$7,$L$6),2,IF(J17>=IF(B17="JSE",$L$7,$L$6)/4,1,0)))) -> 2 | AF17: =IF(C17="","",IF(F17="Short",AND(T17<>"",N(T17)<0),N(T17)>0)+(N(S17)>=1.5)) -> 1 | AG17: =IF(C17="","",IF(AL17="",0,IF(AL17>=3,4,IF(AL17>=2,2,0)))) -> 4 | AH17: =IF(C17="","",IF(AND(ISNUMBER(V17),ISNUMBER(A17),V17>=A17,V17-A17<=14),-2,0)) -> 0 | AI17: =IF(C17="","",IF(AND(F17="Short",N(U17)>=0.2),-1,0)) -> 0 | AJ17: =IF(C17="","",SUM(AB17:AI17)) -> 16 | AK17: =IF(C17="","",IF(AJ17>=14,"A",IF(AJ17>=10,"B","C"))) -> A | AL17: =IFERROR(IF(OR(Y17="",Z17="",AA17=""),"",IF(F17="Short",IF(Z17<=Y17,"",(Y17-AA17)/(Z17-Y17)),IF(Y17<=Z17,"",(AA17-Y17)/(Y17-Z17)))),"") -> 3 | AM17: =IF(OR(Y17="",Z17="",N(Y17)=N(Z17)),"",IF(OR(AND(F17="Short",Z17<Y17),AND(NOT(F17="Short"),Z17>Y17)),"stop on wrong side",ABS(Y17-Z17))) -> 2.26 | AN17: =IFERROR(IF(OR(NOT(ISNUMBER(AM17)),$C$6=""),"",ROUNDDOWN($C$6*$C$7/AM17,2)),"") -> 0.2 | AO17: =IFERROR(IF(AN17="","",AN17*Y17),"") -> 6.98 | AP17: Entry setup | AS17: =IFERROR(IF(OR(AR17="",Y17="",AQ17=""),"",IF(F17="Short",1-AR17/Y17,AR17/Y17-1)),"") | AT17: =IF(AQ17="","",IF(ISNUMBER($C$4),$C$4,TODAY())-AQ17) | AU17: =IF(C17="","",IF(AP17="Open position",IF(IF(F17="Short",AND(ISNUMBER(AR17),ISNUMBER(Z17),AR17>=Z17),AND(ISNUMBER(AR17),ISNUMBER(Z17),AR17<=Z17)),IF(F17="Short","COVER — stop hit (buy back)","SELL — stop hit"),IF(IF(F17="Short",AND(ISNUMBER(AR17),ISNUMBER(AA17),AR17<=AA17),AND(ISNUMBER(AR17),ISNUMBER(AA17),AR17>=AA17)),"TAKE PROFIT — target hit",IF(AND(ISNUMBER(AT17),AT17>182),IF(F17="Short","COVER — 6-month time limit","SELL — 6-month time limit"),IF(AND(ISNUMBER(AT17),AT17>42,ISNUMBER(AS17),AS17<0.02),"REVIEW — no progress after 6 weeks",IF(IF(F17="Short",AND(L17<>"",N(L17)>0),AND(L17<>"",N(L17)<0)),IF(F17="Short","REVIEW — back above 50-day avg","REVIEW — below 50-day avg"),"HOLD"))))),IF(OR(AP17="Closed",AP17="Dropped"),"Closed",IF(AK17="A",IF(F17="Short","Run Technical Review — SHORT entry","Run Technical Review — LONG entry"),IF(AK17="B","Watch — wait for setup","Drop or re-check next week"))))) -> Run Technical Review — SHORT entry | AV17: Trigger: Sell stop below 34.90 (price under the 20-day 35.37 and falling 50/200-day); stop above the 50-day zone. Short entry 34.90, stop 37.16 (2×ATR 1.13), target 28.12 (3R). LRC Work-sheet 14 Oct: SELL (6-m target ~$29.75, -16%; score 3.1/5; technical: NOT CLEARED — score below 70%). SELL (−16%) and full pass on the Finviz short preset. LRC Technical Review rules are written for LONG entries, so "NOT CLEARED / downtrend" here supports a short — PM to confirm. No results date inside 14 days (next ~Dec). Priority short #1. Data 13 Oct close: stockanalysis statistics/history (Finviz-preset replica, short screen); Perf Half vs ~13 Apr close; EPS growth this yr = consensus current FY (adjusted). Perf Quarter n/f (history page holds 50 sessions). Finviz itself blocked for us — same filters applied manually. — P. Nkuna | AX17: =IF(AND(C17<>"",A17=$C$4,ISNUMBER(AJ17)),AJ17+ROW()/100000,"")
A18: 46312 | B18: US | C18: ANET | D18: Arista Networks, Inc. | E18: Technology | F18: Short | G18: 204.52 | H18: 257.95 | I18: 4946200 | J18: =IF(OR(G18="",I18=""),"",G18*I18/1000000) -> 1011.5968 | K18: -0.0089 | L18: 0.0284 | M18: 0.2637 | N18: 50.5 | P18: 0.3453 | Q18: -0.0593 | R18: 0.7859 | S18: 1.61 | T18: 0.3799 | U18: 0.0114 | V18: 46329 | W18: 6.81 | X18: SHORT: Failed breakout / lower high | Y18: 197.4 | Z18: 211.02 | AA18: 156.54 | AB18: =IF(C18="","",IF(F18="Short",(AND(M18<>"",N(M18)<0))+(AND(L18<>"",N(L18)<0))+(AND(K18<>"",N(K18)<0))+AND(L18<>"",M18<>"",N(M18)<N(L18)),(N(M18)>0)+(N(L18)>0)+(N(K18)>0)+AND(L18<>"",M18<>"",N(M18)>N(L18)))) -> 1 | AC18: =IF(C18="","",IF(F18="Short",IF(N18="",0,IF(AND(N18>=30,N18<=50),2,IF(OR(AND(N18>=25,N18<30),AND(N18>50,N18<=60)),1,0)))+IF(P18="",0,IF(AND(IF(B18="JSE",$L$5,$L$4)<>"",P18<IF(B18="JSE",$L$5,$L$4)),2,IF(P18<0,1,0))),IF(N18="",0,IF(AND(N18>=50,N18<=70),2,IF(OR(AND(N18>=40,N18<50),AND(N18>70,N18<=75)),1,0)))+IF(P18="",0,IF(AND(IF(B18="JSE",$L$5,$L$4)<>"",P18>IF(B18="JSE",$L$5,$L$4)),2,IF(P18>0,1,0))))) -> 1 | AD18: =IF(C18="","",IF(F18="Short",IF(R18="",0,IF(R18<=0.1,2,IF(R18<=0.25,1,0))),IF(Q18="",0,IF(Q18>=-0.1,2,IF(Q18>=-0.25,1,0))))) -> 0 | AE18: =IF(C18="","",IF(J18="",0,IF(J18>=IF(B18="JSE",$L$7,$L$6),2,IF(J18>=IF(B18="JSE",$L$7,$L$6)/4,1,0)))) -> 2 | AF18: =IF(C18="","",IF(F18="Short",AND(T18<>"",N(T18)<0),N(T18)>0)+(N(S18)>=1.5)) -> 1 | AG18: =IF(C18="","",IF(AL18="",0,IF(AL18>=3,4,IF(AL18>=2,2,0)))) -> 4 | AH18: =IF(C18="","",IF(AND(ISNUMBER(V18),ISNUMBER(A18),V18>=A18,V18-A18<=14),-2,0)) -> 0 | AI18: =IF(C18="","",IF(AND(F18="Short",N(U18)>=0.2),-1,0)) -> 0 | AJ18: =IF(C18="","",SUM(AB18:AI18)) -> 9 | AK18: =IF(C18="","",IF(AJ18>=14,"A",IF(AJ18>=10,"B","C"))) -> C | AL18: =IFERROR(IF(OR(Y18="",Z18="",AA18=""),"",IF(F18="Short",IF(Z18<=Y18,"",(Y18-AA18)/(Z18-Y18)),IF(Y18<=Z18,"",(AA18-Y18)/(Y18-Z18)))),"") -> 3 | AM18: =IF(OR(Y18="",Z18="",N(Y18)=N(Z18)),"",IF(OR(AND(F18="Short",Z18<Y18),AND(NOT(F18="Short"),Z18>Y18)),"stop on wrong side",ABS(Y18-Z18))) -> 13.62 | AN18: =IFERROR(IF(OR(NOT(ISNUMBER(AM18)),$C$6=""),"",ROUNDDOWN($C$6*$C$7/AM18,2)),"") -> 0.03 | AO18: =IFERROR(IF(AN18="","",AN18*Y18),"") -> 5.922 | AP18: Watch | AS18: =IFERROR(IF(OR(AR18="",Y18="",AQ18=""),"",IF(F18="Short",1-AR18/Y18,AR18/Y18-1)),"") | AT18: =IF(AQ18="","",IF(ISNUMBER($C$4),$C$4,TODAY())-AQ18) | AU18: =IF(C18="","",IF(AP18="Open position",IF(IF(F18="Short",AND(ISNUMBER(AR18),ISNUMBER(Z18),AR18>=Z18),AND(ISNUMBER(AR18),ISNUMBER(Z18),AR18<=Z18)),IF(F18="Short","COVER — stop hit (buy back)","SELL — stop hit"),IF(IF(F18="Short",AND(ISNUMBER(AR18),ISNUMBER(AA18),AR18<=AA18),AND(ISNUMBER(AR18),ISNUMBER(AA18),AR18>=AA18)),"TAKE PROFIT — target hit",IF(AND(ISNUMBER(AT18),AT18>182),IF(F18="Short","COVER — 6-month time limit","SELL — 6-month time limit"),IF(AND(ISNUMBER(AT18),AT18>42,ISNUMBER(AS18),AS18<0.02),"REVIEW — no progress after 6 weeks",IF(IF(F18="Short",AND(L18<>"",N(L18)>0),AND(L18<>"",N(L18)<0)),IF(F18="Short","REVIEW — back above 50-day avg","REVIEW — below 50-day avg"),"HOLD"))))),IF(OR(AP18="Closed",AP18="Dropped"),"Closed",IF(AK18="A",IF(F18="Short","Run Technical Review — SHORT entry","Run Technical Review — LONG entry"),IF(AK18="B","Watch — wait for setup","Drop or re-check next week"))))) -> Drop or re-check next week | AV18: Trigger: Sell stop below the 13 Oct low (197.60) after the failed push to the 52-week high (217.41) on 9 Oct. Short entry 197.40, stop 211.02 (2×ATR 6.81), target 156.54 (3R). LRC Work-sheet 14 Oct: SELL (6-m target ~$144.61, -29%; score 3.7/5; technical: CLEARED — STAGED ENTRY). SELL (−29%) + technical clearance. Carried from last week (old trigger 186 replaced). 13 Oct reversal on 1.6x volume. High beta (1.6): small size. Results 3 Nov. Priority short #2. Data 13 Oct close: stockanalysis statistics + daily history to 13 Oct (SMA20/ATR14 computed); Perf Half vs ~13 Apr close; EPS growth this yr = consensus current FY (adjusted). Perf Quarter n/f (history page holds 50 sessions). Finviz itself blocked for us — same filters applied manually. — P. Nkuna | AX18: =IF(AND(C18<>"",A18=$C$4,ISNUMBER(AJ18)),AJ18+ROW()/100000,"")
A19: 46312 | B19: US | C19: AMD | D19: Advanced Micro Devices, Inc. | E19: Technology | F19: Short | G19: 605.53 | H19: 988.51 | I19: 21561387 | J19: =IF(OR(G19="",I19=""),"",G19*I19/1000000) -> 13056.067 | K19: -0.0044 | L19: 0.1346 | M19: 0.556 | N19: 55.8 | O19: 0.1444 | P19: 1.4532 | Q19: -0.0805 | R19: 2.2171 | S19: 0.83 | T19: 0.819 | U19: 0.0242 | V19: 46329 | W19: 23.77 | X19: SHORT: Failed breakout / lower high | Y19: 569.5 | Z19: 617.04 | AA19: 426.88 | AB19: =IF(C19="","",IF(F19="Short",(AND(M19<>"",N(M19)<0))+(AND(L19<>"",N(L19)<0))+(AND(K19<>"",N(K19)<0))+AND(L19<>"",M19<>"",N(M19)<N(L19)),(N(M19)>0)+(N(L19)>0)+(N(K19)>0)+AND(L19<>"",M19<>"",N(M19)>N(L19)))) -> 1 | AC19: =IF(C19="","",IF(F19="Short",IF(N19="",0,IF(AND(N19>=30,N19<=50),2,IF(OR(AND(N19>=25,N19<30),AND(N19>50,N19<=60)),1,0)))+IF(P19="",0,IF(AND(IF(B19="JSE",$L$5,$L$4)<>"",P19<IF(B19="JSE",$L$5,$L$4)),2,IF(P19<0,1,0))),IF(N19="",0,IF(AND(N19>=50,N19<=70),2,IF(OR(AND(N19>=40,N19<50),AND(N19>70,N19<=75)),1,0)))+IF(P19="",0,IF(AND(IF(B19="JSE",$L$5,$L$4)<>"",P19>IF(B19="JSE",$L$5,$L$4)),2,IF(P19>0,1,0))))) -> 1 | AD19: =IF(C19="","",IF(F19="Short",IF(R19="",0,IF(R19<=0.1,2,IF(R19<=0.25,1,0))),IF(Q19="",0,IF(Q19>=-0.1,2,IF(Q19>=-0.25,1,0))))) -> 0 | AE19: =IF(C19="","",IF(J19="",0,IF(J19>=IF(B19="JSE",$L$7,$L$6),2,IF(J19>=IF(B19="JSE",$L$7,$L$6)/4,1,0)))) -> 2 | AF19: =IF(C19="","",IF(F19="Short",AND(T19<>"",N(T19)<0),N(T19)>0)+(N(S19)>=1.5)) -> 0 | AG19: =IF(C19="","",IF(AL19="",0,IF(AL19>=3,4,IF(AL19>=2,2,0)))) -> 4 | AH19: =IF(C19="","",IF(AND(ISNUMBER(V19),ISNUMBER(A19),V19>=A19,V19-A19<=14),-2,0)) -> 0 | AI19: =IF(C19="","",IF(AND(F19="Short",N(U19)>=0.2),-1,0)) -> 0 | AJ19: =IF(C19="","",SUM(AB19:AI19)) -> 8 | AK19: =IF(C19="","",IF(AJ19>=14,"A",IF(AJ19>=10,"B","C"))) -> C | AL19: =IFERROR(IF(OR(Y19="",Z19="",AA19=""),"",IF(F19="Short",IF(Z19<=Y19,"",(Y19-AA19)/(Z19-Y19)),IF(Y19<=Z19,"",(AA19-Y19)/(Y19-Z19)))),"") -> 3 | AM19: =IF(OR(Y19="",Z19="",N(Y19)=N(Z19)),"",IF(OR(AND(F19="Short",Z19<Y19),AND(NOT(F19="Short"),Z19>Y19)),"stop on wrong side",ABS(Y19-Z19))) -> 47.54 | AN19: =IFERROR(IF(OR(NOT(ISNUMBER(AM19)),$C$6=""),"",ROUNDDOWN($C$6*$C$7/AM19,2)),"") -> 0 | AO19: =IFERROR(IF(AN19="","",AN19*Y19),"") -> 0 | AP19: Watch | AS19: =IFERROR(IF(OR(AR19="",Y19="",AQ19=""),"",IF(F19="Short",1-AR19/Y19,AR19/Y19-1)),"") | AT19: =IF(AQ19="","",IF(ISNUMBER($C$4),$C$4,TODAY())-AQ19) | AU19: =IF(C19="","",IF(AP19="Open position",IF(IF(F19="Short",AND(ISNUMBER(AR19),ISNUMBER(Z19),AR19>=Z19),AND(ISNUMBER(AR19),ISNUMBER(Z19),AR19<=Z19)),IF(F19="Short","COVER — stop hit (buy back)","SELL — stop hit"),IF(IF(F19="Short",AND(ISNUMBER(AR19),ISNUMBER(AA19),AR19<=AA19),AND(ISNUMBER(AR19),ISNUMBER(AA19),AR19>=AA19)),"TAKE PROFIT — target hit",IF(AND(ISNUMBER(AT19),AT19>182),IF(F19="Short","COVER — 6-month time limit","SELL — 6-month time limit"),IF(AND(ISNUMBER(AT19),AT19>42,ISNUMBER(AS19),AS19<0.02),"REVIEW — no progress after 6 weeks",IF(IF(F19="Short",AND(L19<>"",N(L19)>0),AND(L19<>"",N(L19)<0)),IF(F19="Short","REVIEW — back above 50-day avg","REVIEW — below 50-day avg"),"HOLD"))))),IF(OR(AP19="Closed",AP19="Dropped"),"Closed",IF(AK19="A",IF(F19="Short","Run Technical Review — SHORT entry","Run Technical Review — LONG entry"),IF(AK19="B","Watch — wait for setup","Drop or re-check next week"))))) -> Drop or re-check next week | AV19: Trigger: Sell stop below the 15-day swing low (570.60); 52-week high 658.52 was 8% above. Short entry 569.50, stop 617.04 (2×ATR 23.77), target 426.88 (3R). LRC Work-sheet 14 Oct: SELL (6-m target ~$402.73, -33%; score 3.3/5; technical: CLEARED — STAGED ENTRY). SELL (−33%) + technical clearance. Do NOT short strength — act only below the trigger. Beta 2.45: half size. Results 3 Nov. Priority short #3. Data 13 Oct close: stockanalysis statistics/history (Finviz-preset replica, long screen); Perf Half vs ~13 Apr close; EPS growth this yr = consensus current FY (adjusted). Finviz itself blocked for us — same filters applied manually. — P. Nkuna | AX19: =IF(AND(C19<>"",A19=$C$4,ISNUMBER(AJ19)),AJ19+ROW()/100000,"")
